<?xml version="1.0" ?>
<!-- =================================================================================== -->
<!-- |    This document was autogenerated by xacro from /home/vinoth/cynlr_ws/install/flexiv_description/share/flexiv_description/urdf/rizon.urdf.xacro | -->
<!-- |    EDITING THIS FILE BY HAND IS NOT RECOMMENDED                                 | -->
<!-- =================================================================================== -->
<robot name="Rizon4s">
  <!-- base link -->
  <link name="Rizon4s-123456_grav_base_link">
    <inertial>
      <origin rpy="0 0 0" xyz="0 0 0.057"/>
      <mass value="1.186"/>
      <inertia ixx="3E-3" ixy="0" ixz="0" iyy="3E-3" iyz="-0" izz="1E-3"/>
    </inertial>
    <visual>
      <origin rpy="0 0 1.5707963267948966" xyz="0 0 0"/>
      <geometry>
        <mesh filename="/home/vinoth/cynlr_ws/src/flexiv_description/meshes/Grav/visual/base.stl" scale="0.001 0.001 0.001"/>
      </geometry>
      <material name="flexiv_black"/>
    </visual>
    <collision>
      <origin rpy="0 0 1.5707963267948966" xyz="0 0 0"/>
      <geometry>
        <mesh filename="/home/vinoth/cynlr_ws/src/flexiv_description/meshes/Grav/collision/base.stl" scale="0.001 0.001 0.001"/>
      </geometry>
    </collision>
  </link>
  <!-- left finger links -->
  <link name="Rizon4s-123456_left_outer_bar">
    <inertial>
      <origin rpy="0 0 0" xyz="0 0 0.029"/>
      <mass value="1E-4"/>
      <inertia ixx="1E-7" ixy="0" ixz="0" iyy="1E-7" iyz="0" izz="1E-7"/>
    </inertial>
    <visual>
      <origin rpy="0 0 1.5707963267948966" xyz="0 0 0"/>
      <geometry>
        <mesh filename="/home/vinoth/cynlr_ws/src/flexiv_description/meshes/Grav/visual/outer_bar.stl" scale="0.001 0.001 0.001"/>
      </geometry>
      <material name="flexiv_black"/>
    </visual>
    <collision>
      <origin rpy="0 0 1.5707963267948966" xyz="0 0 0"/>
      <geometry>
        <mesh filename="/home/vinoth/cynlr_ws/src/flexiv_description/meshes/Grav/collision/outer_bar.stl" scale="0.001 0.001 0.001"/>
      </geometry>
    </collision>
  </link>
  <link name="Rizon4s-123456_left_inner_bar">
    <inertial>
      <origin rpy="0 0 0" xyz="0 0 0.029"/>
      <mass value="1E-4"/>
      <inertia ixx="1E-7" ixy="0" ixz="0" iyy="1E-7" iyz="0" izz="1E-7"/>
    </inertial>
    <visual>
      <origin rpy="0 0 1.5707963267948966" xyz="0 0 0"/>
      <geometry>
        <mesh filename="/home/vinoth/cynlr_ws/src/flexiv_description/meshes/Grav/visual/inner_bar.stl" scale="0.001 0.001 0.001"/>
      </geometry>
      <material name="flexiv_black"/>
    </visual>
    <collision>
      <origin rpy="0 0 1.5707963267948966" xyz="0 0 0"/>
      <geometry>
        <mesh filename="/home/vinoth/cynlr_ws/src/flexiv_description/meshes/Grav/collision/inner_bar.stl" scale="0.001 0.001 0.001"/>
      </geometry>
    </collision>
  </link>
  <link name="Rizon4s-123456_left_finger_mount">
    <inertial>
      <origin rpy="0 0 0" xyz="0 0 0"/>
      <mass value="1E-4"/>
      <inertia ixx="1E-7" ixy="0" ixz="0" iyy="1E-7" iyz="0" izz="1E-7"/>
    </inertial>
    <visual>
      <origin rpy="0 0 1.5707963267948966" xyz="0 0 0"/>
      <geometry>
        <mesh filename="/home/vinoth/cynlr_ws/src/flexiv_description/meshes/Grav/visual/finger_mount.stl" scale="0.001 0.001 0.001"/>
      </geometry>
      <material name="flexiv_black"/>
    </visual>
  </link>
  <link name="Rizon4s-123456_left_finger_tip">
    <inertial>
      <origin rpy="0 0 0" xyz="0 0 0"/>
      <mass value="0"/>
      <inertia ixx="0" ixy="0" ixz="0" iyy="0" iyz="0" izz="0"/>
    </inertial>
    <visual>
      <origin rpy="0 0 1.5707963267948966" xyz="0 0 0"/>
      <geometry>
        <mesh filename="/home/vinoth/cynlr_ws/src/flexiv_description/meshes/Grav/visual/finger_tip.obj" scale="0.001 0.001 0.001"/>
      </geometry>
    </visual>
    <collision>
      <origin rpy="0 0 1.5707963267948966" xyz="0 0 0"/>
      <geometry>
        <mesh filename="/home/vinoth/cynlr_ws/src/flexiv_description/meshes/Grav/collision/finger_tip.stl" scale="0.001 0.001 0.001"/>
      </geometry>
    </collision>
  </link>
  <!-- right finger links -->
  <link name="Rizon4s-123456_right_outer_bar">
    <inertial>
      <origin rpy="0 0 0" xyz="0 0 0.029"/>
      <mass value="1E-4"/>
      <inertia ixx="1E-7" ixy="0" ixz="0" iyy="1E-7" iyz="0" izz="1E-7"/>
    </inertial>
    <visual>
      <origin rpy="0 0 1.5707963267948966" xyz="0 0 0"/>
      <geometry>
        <mesh filename="/home/vinoth/cynlr_ws/src/flexiv_description/meshes/Grav/visual/outer_bar.stl" scale="0.001 0.001 0.001"/>
      </geometry>
      <material name="flexiv_black"/>
    </visual>
    <collision>
      <origin rpy="0 0 1.5707963267948966" xyz="0 0 0"/>
      <geometry>
        <mesh filename="/home/vinoth/cynlr_ws/src/flexiv_description/meshes/Grav/collision/outer_bar.stl" scale="0.001 0.001 0.001"/>
      </geometry>
    </collision>
  </link>
  <link name="Rizon4s-123456_right_inner_bar">
    <inertial>
      <origin rpy="0 0 0" xyz="0 0 0.029"/>
      <mass value="1E-4"/>
      <inertia ixx="1E-7" ixy="0" ixz="0" iyy="1E-7" iyz="0" izz="1E-7"/>
    </inertial>
    <visual>
      <origin rpy="0 0 1.5707963267948966" xyz="0 0 0"/>
      <geometry>
        <mesh filename="/home/vinoth/cynlr_ws/src/flexiv_description/meshes/Grav/visual/inner_bar.stl" scale="0.001 0.001 0.001"/>
      </geometry>
      <material name="flexiv_black"/>
    </visual>
    <collision>
      <origin rpy="0 0 1.5707963267948966" xyz="0 0 0"/>
      <geometry>
        <mesh filename="/home/vinoth/cynlr_ws/src/flexiv_description/meshes/Grav/collision/inner_bar.stl" scale="0.001 0.001 0.001"/>
      </geometry>
    </collision>
  </link>
  <link name="Rizon4s-123456_right_finger_mount">
    <inertial>
      <origin rpy="0 0 0" xyz="0 0 0"/>
      <mass value="1E-4"/>
      <inertia ixx="1E-7" ixy="0" ixz="0" iyy="1E-7" iyz="0" izz="1E-7"/>
    </inertial>
    <visual>
      <origin rpy="0 0 1.5707963267948966" xyz="0 0 0"/>
      <geometry>
        <mesh filename="/home/vinoth/cynlr_ws/src/flexiv_description/meshes/Grav/visual/finger_mount.stl" scale="0.001 0.001 0.001"/>
      </geometry>
      <material name="flexiv_black"/>
    </visual>
  </link>
  <link name="Rizon4s-123456_right_finger_tip">
    <inertial>
      <origin rpy="0 0 0" xyz="0 0 0"/>
      <mass value="0"/>
      <inertia ixx="0" ixy="0" ixz="0" iyy="0" iyz="0" izz="0"/>
    </inertial>
    <visual>
      <origin rpy="0 0 1.5707963267948966" xyz="0 0 0"/>
      <geometry>
        <mesh filename="/home/vinoth/cynlr_ws/src/flexiv_description/meshes/Grav/visual/finger_tip.obj" scale="0.001 0.001 0.001"/>
      </geometry>
    </visual>
    <collision>
      <origin rpy="0 0 1.5707963267948966" xyz="0 0 0"/>
      <geometry>
        <mesh filename="/home/vinoth/cynlr_ws/src/flexiv_description/meshes/Grav/collision/finger_tip.stl" scale="0.001 0.001 0.001"/>
      </geometry>
    </collision>
  </link>
  <!-- TCP links -->
  <link name="Rizon4s-123456_grav_tcp">
    <!-- open finger, used by RCA -->
    <inertial>
      <origin rpy="0 0 0" xyz="0 0 0"/>
      <mass value="0"/>
      <inertia ixx="0" ixy="0" ixz="0" iyy="0" iyz="0" izz="0"/>
    </inertial>
  </link>
  <link name="Rizon4s-123456_closed_fingers_tcp">
    <inertial>
      <origin rpy="0 0 0" xyz="0 0 0"/>
      <mass value="0"/>
      <inertia ixx="0" ixy="0" ixz="0" iyy="0" iyz="0" izz="0"/>
    </inertial>
  </link>
  <link name="Rizon4s-123456_left_finger_tcp">
    <inertial>
      <origin rpy="0 0 0" xyz="0 0 0"/>
      <mass value="0"/>
      <inertia ixx="0" ixy="0" ixz="0" iyy="0" iyz="0" izz="0"/>
    </inertial>
  </link>
  <link name="Rizon4s-123456_right_finger_tcp">
    <inertial>
      <origin rpy="0 0 0" xyz="0 0 0"/>
      <mass value="0"/>
      <inertia ixx="0" ixy="0" ixz="0" iyy="0" iyz="0" izz="0"/>
    </inertial>
  </link>
  <!-- JOINTS -->
  <joint name="Rizon4s-123456_open_fingers_tcp_joint" type="fixed">
    <origin rpy="0 0 0" xyz="0 0 0.15"/>
    <parent link="Rizon4s-123456_grav_base_link"/>
    <child link="Rizon4s-123456_grav_tcp"/>
    <axis xyz="0 0 1"/>
  </joint>
  <joint name="Rizon4s-123456_closed_fingers_tcp_joint" type="fixed">
    <origin rpy="0 0 0" xyz="0 0 0.20"/>
    <parent link="Rizon4s-123456_grav_base_link"/>
    <child link="Rizon4s-123456_closed_fingers_tcp"/>
    <axis xyz="0 0 1"/>
  </joint>
  <!-- left finger joints -->
  <joint name="Rizon4s-123456_left_outer_knuckle_joint" type="revolute">
    <origin rpy="0 0 0" xyz="0 -0.0325 0.0825"/>
    <parent link="Rizon4s-123456_grav_base_link"/>
    <child link="Rizon4s-123456_left_outer_bar"/>
    <axis xyz="1 0 0"/>
    <limit effort="0" lower="-0.155" upper="0.7854" velocity="2.0"/>
    <mimic joint="Rizon4s-123456_finger_width_joint" multiplier="9.404" offset="-0.155"/>
  </joint>
  <joint name="Rizon4s-123456_left_inner_knuckle_joint" type="revolute">
    <origin rpy="0 0 0" xyz="0 -0.0165 0.0995"/>
    <parent link="Rizon4s-123456_grav_base_link"/>
    <child link="Rizon4s-123456_left_inner_bar"/>
    <axis xyz="1 0 0"/>
    <limit effort="0" lower="-0.155" upper="0.7854" velocity="2.0"/>
    <mimic joint="Rizon4s-123456_left_outer_knuckle_joint" multiplier="1" offset="0"/>
  </joint>
  <joint name="Rizon4s-123456_left_inner_finger_joint" type="revolute">
    <origin rpy="0 0 0" xyz="0 0 0.058"/>
    <parent link="Rizon4s-123456_left_outer_bar"/>
    <child link="Rizon4s-123456_left_finger_mount"/>
    <axis xyz="1 0 0"/>
    <limit effort="0" lower="-0.7854" upper="0.155" velocity="2.0"/>
    <mimic joint="Rizon4s-123456_left_outer_knuckle_joint" multiplier="-1" offset="0"/>
  </joint>
  <joint name="Rizon4s-123456_left_inner_finger_pad_joint" type="fixed">
    <origin rpy="0 0 0" xyz="0 0.010 0.0235"/>
    <parent link="Rizon4s-123456_left_finger_mount"/>
    <child link="Rizon4s-123456_left_finger_tip"/>
    <axis xyz="0 0 1"/>
  </joint>
  <joint name="Rizon4s-123456_left_finger_tcp_joint" type="fixed">
    <origin rpy="0 0 0" xyz="0 0.0135 0.036"/>
    <parent link="Rizon4s-123456_left_finger_tip"/>
    <child link="Rizon4s-123456_left_finger_tcp"/>
    <axis xyz="0 0 1"/>
  </joint>
  <!-- right finger joints -->
  <joint name="Rizon4s-123456_right_outer_knuckle_joint" type="revolute">
    <origin rpy="0 0 3.141592653589793" xyz="0 0.0325 0.0825"/>
    <parent link="Rizon4s-123456_grav_base_link"/>
    <child link="Rizon4s-123456_right_outer_bar"/>
    <axis xyz="1 0 0"/>
    <limit effort="0" lower="-0.155" upper="0.7854" velocity="2.0"/>
    <mimic joint="Rizon4s-123456_left_outer_knuckle_joint" multiplier="1" offset="0"/>
  </joint>
  <joint name="Rizon4s-123456_right_inner_knuckle_joint" type="revolute">
    <origin rpy="0 0 3.141592653589793" xyz="0 0.0165 0.0995"/>
    <parent link="Rizon4s-123456_grav_base_link"/>
    <child link="Rizon4s-123456_right_inner_bar"/>
    <axis xyz="1 0 0"/>
    <limit effort="0" lower="-0.155" upper="0.7854" velocity="2.0"/>
    <mimic joint="Rizon4s-123456_left_outer_knuckle_joint" multiplier="1" offset="0"/>
  </joint>
  <joint name="Rizon4s-123456_right_inner_finger_joint" type="revolute">
    <origin rpy="0 0 0" xyz="0 0 0.058"/>
    <parent link="Rizon4s-123456_right_outer_bar"/>
    <child link="Rizon4s-123456_right_finger_mount"/>
    <axis xyz="1 0 0"/>
    <limit effort="0" lower="-0.7854" upper="0.155" velocity="2.0"/>
    <mimic joint="Rizon4s-123456_left_outer_knuckle_joint" multiplier="-1" offset="0"/>
  </joint>
  <joint name="Rizon4s-123456_right_inner_finger_pad_joint" type="fixed">
    <origin rpy="0 0 0" xyz="0 0.010 0.0235"/>
    <parent link="Rizon4s-123456_right_finger_mount"/>
    <child link="Rizon4s-123456_right_finger_tip"/>
    <axis xyz="0 0 1"/>
  </joint>
  <joint name="Rizon4s-123456_right_finger_tcp_joint" type="fixed">
    <origin rpy="0 0 0" xyz="0 0.0135 0.036"/>
    <parent link="Rizon4s-123456_right_finger_tip"/>
    <child link="Rizon4s-123456_right_finger_tcp"/>
    <axis xyz="0 0 1"/>
  </joint>
  <!--
  Control joint.
  Should we replace this with transmission?
  Note: This virtual joint should be prismatic,
        but it must be revolute to match the mimic joint.
        The unused link cannot have 0 mass.
  -->
  <joint name="Rizon4s-123456_finger_width_joint" type="revolute">
    <origin rpy="0 0 0" xyz="0 0 0"/>
    <parent link="Rizon4s-123456_grav_base_link"/>
    <child link="Rizon4s-123456_unused_finger_width_link"/>
    <axis xyz="1 0 0"/>
    <limit effort="80" lower="0" upper="0.100" velocity="0.2"/>
  </joint>
  <link name="Rizon4s-123456_unused_finger_width_link">
    <inertial>
      <origin rpy="0 0 0" xyz="0 0 0"/>
      <mass value="1E-4"/>
      <inertia ixx="1E-7" ixy="0" ixz="0" iyy="1E-7" iyz="0" izz="1E-7"/>
    </inertial>
  </link>
  <!-- Connect the gripper to the robot flange link -->
  <joint name="Rizon4s-123456_gripper_base_joint" type="fixed">
    <origin rpy="0 0 0" xyz="0 0 0"/>
    <parent link="Rizon4s-123456_flange"/>
    <child link="Rizon4s-123456_grav_base_link"/>
  </joint>
  <!-- materials -->
  <material name="flexiv_black">
    <color rgba="0.22 0.22 0.22 1"/>
  </material>
  <joint name="Rizon4s-123456_base_joint" type="fixed">
    <parent link="world"/>
    <child link="Rizon4s-123456_base_link"/>
    <origin rpy="0.0 0.0 0.0" xyz="0.0 0.0 0.0"/>
  </joint>
  <joint name="Rizon4s-123456_joint1" type="revolute">
    <parent link="Rizon4s-123456_base_link"/>
    <child link="Rizon4s-123456_link1"/>
    <origin rpy="0 0 -3.141592654" xyz="0 0 0.155"/>
    <axis xyz="0 0 1"/>
    <limit effort="123" lower="-2.8798" upper="2.8798" velocity="2.0944"/>
    <safety_controller k_position="100.0" k_velocity="40.0" soft_lower_limit="-2.7925" soft_upper_limit="2.7925"/>
  </joint>
  <joint name="Rizon4s-123456_joint2" type="revolute">
    <parent link="Rizon4s-123456_link1"/>
    <child link="Rizon4s-123456_link2"/>
    <origin rpy="0 0 0" xyz="0 0.03 0.21"/>
    <axis xyz="0 1 0"/>
    <limit effort="123" lower="-2.3562" upper="2.3562" velocity="2.0944"/>
    <safety_controller k_position="100.0" k_velocity="40.0" soft_lower_limit="-2.2689" soft_upper_limit="2.2689"/>
  </joint>
  <joint name="Rizon4s-123456_joint3" type="revolute">
    <parent link="Rizon4s-123456_link2"/>
    <child link="Rizon4s-123456_link3"/>
    <origin rpy="0 0 0" xyz="0 0.035 0.205"/>
    <axis xyz="0 0 1"/>
    <limit effort="64" lower="-3.0543" upper="3.0543" velocity="2.4435"/>
    <safety_controller k_position="100.0" k_velocity="40.0" soft_lower_limit="-2.9671" soft_upper_limit="2.9671"/>
  </joint>
  <joint name="Rizon4s-123456_joint4" type="revolute">
    <parent link="Rizon4s-123456_link3"/>
    <child link="Rizon4s-123456_link4"/>
    <origin rpy="0 0 -3.141592654" xyz="-0.02 -0.03 0.19"/>
    <axis xyz="0 1 0"/>
    <limit effort="64" lower="-1.9548" upper="2.7751" velocity="2.4435"/>
    <safety_controller k_position="100.0" k_velocity="40.0" soft_lower_limit="-1.8675" soft_upper_limit="2.6878"/>
  </joint>
  <joint name="Rizon4s-123456_joint5" type="revolute">
    <parent link="Rizon4s-123456_link4"/>
    <child link="Rizon4s-123456_link5"/>
    <origin rpy="0 0 -3.141592654" xyz="-0.02 0.025 0.195"/>
    <axis xyz="0 0 1"/>
    <limit effort="39" lower="-3.0543" upper="3.0543" velocity="4.8869"/>
    <safety_controller k_position="100.0" k_velocity="40.0" soft_lower_limit="-2.9671" soft_upper_limit="2.9671"/>
  </joint>
  <joint name="Rizon4s-123456_joint6" type="revolute">
    <parent link="Rizon4s-123456_link5"/>
    <child link="Rizon4s-123456_link6"/>
    <origin rpy="0 0 0" xyz="0 0.03 0.19"/>
    <axis xyz="0 1 0"/>
    <limit effort="39" lower="-1.4835" upper="4.6251" velocity="4.8869"/>
    <safety_controller k_position="100.0" k_velocity="40.0" soft_lower_limit="-1.3963" soft_upper_limit="4.5379"/>
  </joint>
  <joint name="Rizon4s-123456_joint7" type="revolute">
    <parent link="Rizon4s-123456_link6"/>
    <child link="Rizon4s-123456_link7"/>
    <origin rpy="0 -1.570796327 0" xyz="-0.015 0.073 0.11"/>
    <axis xyz="0 0 1"/>
    <limit effort="39" lower="-3.0543" upper="3.0543" velocity="4.8869"/>
    <safety_controller k_position="100.0" k_velocity="40.0" soft_lower_limit="-2.9671" soft_upper_limit="2.9671"/>
  </joint>
  <joint name="Rizon4s-123456_link7_to_flange" type="fixed">
    <parent link="Rizon4s-123456_link7"/>
    <child link="Rizon4s-123456_flange"/>
    <origin rpy="0 0 -3.141592654" xyz="0 0 0.124"/>
  </joint>
  <link name="world">
      </link>
  <link name="Rizon4s-123456_base_link">
    <inertial>
      <origin rpy="0.0 0.0 0.0" xyz="0.0 -0.0 0.09"/>
      <mass value="3.8"/>
      <inertia ixx="0.02" ixy="0.0" ixz="0.0" iyy="0.02" iyz="0.0" izz="0.01"/>
    </inertial>
    <visual name="shell">
      <origin rpy="0 0 0" xyz="0 0 0"/>
      <geometry>
        <mesh filename="/home/vinoth/cynlr_ws/src/flexiv_description/meshes/Rizon4s/visual/link0.obj"/>
      </geometry>
    </visual>
    <collision name="convex_mesh1">
      <origin rpy="0 0 0" xyz="0 0 0"/>
      <geometry>
        <mesh filename="/home/vinoth/cynlr_ws/src/flexiv_description/meshes/Rizon4s/collision/link0.stl"/>
      </geometry>
    </collision>
  </link>
  <link name="Rizon4s-123456_link1">
    <inertial>
      <origin rpy="0.0 0.0 0.0" xyz="0.0 0.0 0.15"/>
      <mass value="3.6"/>
      <inertia ixx="0.03" ixy="0.0" ixz="0.0" iyy="0.03" iyz="0.0" izz="0.01"/>
    </inertial>
    <visual name="shell">
      <origin rpy="0 0 0" xyz="0 0 0"/>
      <geometry>
        <mesh filename="/home/vinoth/cynlr_ws/src/flexiv_description/meshes/Rizon4s/visual/link1.obj"/>
      </geometry>
    </visual>
    <visual name="ring">
      <origin rpy="0.0 0.0 0.0" xyz="0.0 0.0 -0.0025"/>
      <geometry>
        <mesh filename="/home/vinoth/cynlr_ws/src/flexiv_description/meshes/Rizon4s/visual/ring.obj" scale="0.062 0.062 0.002"/>
      </geometry>
    </visual>
    <collision name="convex_mesh2">
      <origin rpy="0 0 0" xyz="0 0 0"/>
      <geometry>
        <mesh filename="/home/vinoth/cynlr_ws/src/flexiv_description/meshes/Rizon4s/collision/link1.stl"/>
      </geometry>
    </collision>
  </link>
  <link name="Rizon4s-123456_link2">
    <inertial>
      <origin rpy="0.0 0.0 0.0" xyz="-0.0 0.04 0.1"/>
      <mass value="2.7"/>
      <inertia ixx="0.02" ixy="0.0" ixz="0.0" iyy="0.02" iyz="-0.0003" izz="0.004"/>
    </inertial>
    <visual name="shell">
      <origin rpy="0 0 0" xyz="0 0 0"/>
      <geometry>
        <mesh filename="/home/vinoth/cynlr_ws/src/flexiv_description/meshes/Rizon4s/visual/link2.obj"/>
      </geometry>
    </visual>
    <visual name="ring">
      <origin rpy="1.570796327 0.0 0.0" xyz="0.0 -0.0025 0.0"/>
      <geometry>
        <mesh filename="/home/vinoth/cynlr_ws/src/flexiv_description/meshes/Rizon4s/visual/ring.obj" scale="0.062 0.062 0.002"/>
      </geometry>
    </visual>
    <collision name="convex_mesh3">
      <origin rpy="0 0 0" xyz="0 0 0"/>
      <geometry>
        <mesh filename="/home/vinoth/cynlr_ws/src/flexiv_description/meshes/Rizon4s/collision/link2.stl"/>
      </geometry>
    </collision>
  </link>
  <link name="Rizon4s-123456_link3">
    <inertial>
      <origin rpy="0.0 0.0 0.0" xyz="-0.01 -0.0 0.14"/>
      <mass value="2.4"/>
      <inertia ixx="0.01" ixy="0.0" ixz="-0.001" iyy="0.01" iyz="-0.0007" izz="0.004"/>
    </inertial>
    <visual name="shell">
      <origin rpy="0 0 0" xyz="0 0 0"/>
      <geometry>
        <mesh filename="/home/vinoth/cynlr_ws/src/flexiv_description/meshes/Rizon4s/visual/link3.obj"/>
      </geometry>
    </visual>
    <visual name="ring">
      <origin rpy="0.0 0.0 0.0" xyz="0.0 0.0 -0.0025"/>
      <geometry>
        <mesh filename="/home/vinoth/cynlr_ws/src/flexiv_description/meshes/Rizon4s/visual/ring.obj" scale="0.051 0.051 0.002"/>
      </geometry>
    </visual>
    <collision name="convex_mesh4">
      <origin rpy="0 0 0" xyz="0 0 0"/>
      <geometry>
        <mesh filename="/home/vinoth/cynlr_ws/src/flexiv_description/meshes/Rizon4s/collision/link3.stl"/>
      </geometry>
    </collision>
  </link>
  <link name="Rizon4s-123456_link4">
    <inertial>
      <origin rpy="0.0 0.0 0.0" xyz="-0.01 0.03 0.1"/>
      <mass value="2.4"/>
      <inertia ixx="0.02" ixy="0.0" ixz="-0.002" iyy="0.02" iyz="-0.001" izz="0.003"/>
    </inertial>
    <visual name="shell">
      <origin rpy="0 0 0" xyz="0 0 0"/>
      <geometry>
        <mesh filename="/home/vinoth/cynlr_ws/src/flexiv_description/meshes/Rizon4s/visual/link4.obj"/>
      </geometry>
    </visual>
    <visual name="ring">
      <origin rpy="1.570796327 0.0 0.0" xyz="0.0 -0.0025 0.0"/>
      <geometry>
        <mesh filename="/home/vinoth/cynlr_ws/src/flexiv_description/meshes/Rizon4s/visual/ring.obj" scale="0.051 0.051 0.002"/>
      </geometry>
    </visual>
    <collision name="convex_mesh5">
      <origin rpy="0 0 0" xyz="0 0 0"/>
      <geometry>
        <mesh filename="/home/vinoth/cynlr_ws/src/flexiv_description/meshes/Rizon4s/collision/link4.stl"/>
      </geometry>
    </collision>
  </link>
  <link name="Rizon4s-123456_link5">
    <inertial>
      <origin rpy="0.0 0.0 0.0" xyz="0.0 0.0 0.14"/>
      <mass value="2.3"/>
      <inertia ixx="0.01" ixy="0.0" ixz="0.0" iyy="0.01" iyz="0.001" izz="0.004"/>
    </inertial>
    <visual name="shell">
      <origin rpy="0 0 0" xyz="0 0 0"/>
      <geometry>
        <mesh filename="/home/vinoth/cynlr_ws/src/flexiv_description/meshes/Rizon4s/visual/link5.obj"/>
      </geometry>
    </visual>
    <visual name="ring">
      <origin rpy="0.0 0.0 0.0" xyz="0.0 0.0 -0.0025"/>
      <geometry>
        <mesh filename="/home/vinoth/cynlr_ws/src/flexiv_description/meshes/Rizon4s/visual/ring.obj" scale="0.051 0.051 0.002"/>
      </geometry>
    </visual>
    <collision name="convex_mesh6">
      <origin rpy="0 0 0" xyz="0 0 0"/>
      <geometry>
        <mesh filename="/home/vinoth/cynlr_ws/src/flexiv_description/meshes/Rizon4s/collision/link5.stl"/>
      </geometry>
    </collision>
  </link>
  <link name="Rizon4s-123456_link6">
    <inertial>
      <origin rpy="0.0 0.0 0.0" xyz="0.02 0.06 0.07"/>
      <mass value="2.2"/>
      <inertia ixx="0.01" ixy="0.0" ixz="-0.001" iyy="0.01" iyz="0.002" izz="0.004"/>
    </inertial>
    <visual name="shell">
      <origin rpy="0 0 0" xyz="0 0 0"/>
      <geometry>
        <mesh filename="/home/vinoth/cynlr_ws/src/flexiv_description/meshes/Rizon4s/visual/link6.obj"/>
      </geometry>
    </visual>
    <visual name="ring">
      <origin rpy="1.570796327 0.0 0.0" xyz="0.0 -0.0025 0.0"/>
      <geometry>
        <mesh filename="/home/vinoth/cynlr_ws/src/flexiv_description/meshes/Rizon4s/visual/ring.obj" scale="0.051 0.051 0.002"/>
      </geometry>
    </visual>
    <collision name="convex_mesh7">
      <origin rpy="0 0 0" xyz="0 0 0"/>
      <geometry>
        <mesh filename="/home/vinoth/cynlr_ws/src/flexiv_description/meshes/Rizon4s/collision/link6.stl"/>
      </geometry>
    </collision>
  </link>
  <link name="Rizon4s-123456_link7">
    <inertial>
      <origin rpy="0.0 0.0 0.0" xyz="0.0 0.0 0.05"/>
      <mass value="1.4"/>
      <inertia ixx="0.001" ixy="0.0" ixz="0.0" iyy="0.001" iyz="0.0" izz="0.001"/>
    </inertial>
    <visual name="shell">
      <origin rpy="0 0 0" xyz="0 0 0"/>
      <geometry>
        <mesh filename="/home/vinoth/cynlr_ws/src/flexiv_description/meshes/Rizon4s/visual/link7.obj"/>
      </geometry>
    </visual>
    <visual name="ring">
      <origin rpy="0.0 0.0 0.0" xyz="0.0 0.0 -0.0025"/>
      <geometry>
        <mesh filename="/home/vinoth/cynlr_ws/src/flexiv_description/meshes/Rizon4s/visual/ring.obj" scale="0.051 0.051 0.002"/>
      </geometry>
    </visual>
    <collision name="convex_mesh8">
      <origin rpy="0 0 0" xyz="0 0 0"/>
      <geometry>
        <mesh filename="/home/vinoth/cynlr_ws/src/flexiv_description/meshes/Rizon4s/collision/link7.stl"/>
      </geometry>
    </collision>
  </link>
  <link name="Rizon4s-123456_flange">
    </link>
</robot>
